User come this  127.0.0.1on page
Homepage was accessed at 2022-04-26 10:47:46.949633 hours! with that  
Internal Server Error: /login
Traceback (most recent call last):
  File "C:\Users\Innovo\PycharmProjects\linkedmatrix\venv\lib\site-packages\django_redis\cache.py", line 31, in _decorator
    return method(self, *args, **kwargs)
  File "C:\Users\Innovo\PycharmProjects\linkedmatrix\venv\lib\site-packages\django_redis\cache.py", line 98, in _get
    return self.client.get(key, default=default, version=version, client=client)
  File "C:\Users\Innovo\PycharmProjects\linkedmatrix\venv\lib\site-packages\django_redis\client\default.py", line 260, in get
    raise ConnectionInterrupted(connection=client) from e
django_redis.exceptions.ConnectionInterrupted: Redis ConnectionError: Error 10061 connecting to 127.0.0.1:6379. No connection could be made because the target machine actively refused it.

During handling of the above exception, another exception occurred:

Traceback (most recent call last):
  File "C:\Users\Innovo\PycharmProjects\linkedmatrix\venv\lib\site-packages\django\core\handlers\exception.py", line 55, in inner
    response = get_response(request)
  File "C:\Users\Innovo\PycharmProjects\linkedmatrix\custommiddle\mysite\middlewares.py", line 29, in my_ip
    ipcome = cache.get(ip)
  File "C:\Users\Innovo\PycharmProjects\linkedmatrix\venv\lib\site-packages\django_redis\cache.py", line 91, in get
    value = self._get(key, default, version, client)
  File "C:\Users\Innovo\PycharmProjects\linkedmatrix\venv\lib\site-packages\django_redis\cache.py", line 38, in _decorator
    raise e.__cause__
  File "C:\Users\Innovo\PycharmProjects\linkedmatrix\venv\lib\site-packages\django_redis\client\default.py", line 258, in get
    value = client.get(key)
  File "C:\Users\Innovo\PycharmProjects\linkedmatrix\venv\lib\site-packages\redis\commands\core.py", line 1600, in get
    return self.execute_command("GET", name)
  File "C:\Users\Innovo\PycharmProjects\linkedmatrix\venv\lib\site-packages\redis\client.py", line 1215, in execute_command
    conn = self.connection or pool.get_connection(command_name, **options)
  File "C:\Users\Innovo\PycharmProjects\linkedmatrix\venv\lib\site-packages\redis\connection.py", line 1386, in get_connection
    connection.connect()
  File "C:\Users\Innovo\PycharmProjects\linkedmatrix\venv\lib\site-packages\redis\connection.py", line 620, in connect
    raise ConnectionError(self._error_message(e))
redis.exceptions.ConnectionError: Error 10061 connecting to 127.0.0.1:6379. No connection could be made because the target machine actively refused it.
User come this  127.0.0.1on page
Homepage was accessed at 2022-04-26 10:47:46.949633 hours! with that  
Internal Server Error: /admin/
Traceback (most recent call last):
  File "C:\Users\Innovo\PycharmProjects\linkedmatrix\venv\lib\site-packages\django_redis\cache.py", line 31, in _decorator
    return method(self, *args, **kwargs)
  File "C:\Users\Innovo\PycharmProjects\linkedmatrix\venv\lib\site-packages\django_redis\cache.py", line 98, in _get
    return self.client.get(key, default=default, version=version, client=client)
  File "C:\Users\Innovo\PycharmProjects\linkedmatrix\venv\lib\site-packages\django_redis\client\default.py", line 260, in get
    raise ConnectionInterrupted(connection=client) from e
django_redis.exceptions.ConnectionInterrupted: Redis ConnectionError: Error 10061 connecting to 127.0.0.1:6379. No connection could be made because the target machine actively refused it.

During handling of the above exception, another exception occurred:

Traceback (most recent call last):
  File "C:\Users\Innovo\PycharmProjects\linkedmatrix\venv\lib\site-packages\django\core\handlers\exception.py", line 55, in inner
    response = get_response(request)
  File "C:\Users\Innovo\PycharmProjects\linkedmatrix\custommiddle\mysite\middlewares.py", line 29, in my_ip
    ipcome = cache.get(ip)
  File "C:\Users\Innovo\PycharmProjects\linkedmatrix\venv\lib\site-packages\django_redis\cache.py", line 91, in get
    value = self._get(key, default, version, client)
  File "C:\Users\Innovo\PycharmProjects\linkedmatrix\venv\lib\site-packages\django_redis\cache.py", line 38, in _decorator
    raise e.__cause__
  File "C:\Users\Innovo\PycharmProjects\linkedmatrix\venv\lib\site-packages\django_redis\client\default.py", line 258, in get
    value = client.get(key)
  File "C:\Users\Innovo\PycharmProjects\linkedmatrix\venv\lib\site-packages\redis\commands\core.py", line 1600, in get
    return self.execute_command("GET", name)
  File "C:\Users\Innovo\PycharmProjects\linkedmatrix\venv\lib\site-packages\redis\client.py", line 1215, in execute_command
    conn = self.connection or pool.get_connection(command_name, **options)
  File "C:\Users\Innovo\PycharmProjects\linkedmatrix\venv\lib\site-packages\redis\connection.py", line 1386, in get_connection
    connection.connect()
  File "C:\Users\Innovo\PycharmProjects\linkedmatrix\venv\lib\site-packages\redis\connection.py", line 620, in connect
    raise ConnectionError(self._error_message(e))
redis.exceptions.ConnectionError: Error 10061 connecting to 127.0.0.1:6379. No connection could be made because the target machine actively refused it.
User come this  127.0.0.1on page
Homepage was accessed at 2022-04-26 10:47:46.949633 hours! with that  
Internal Server Error: /favicon.ico
Traceback (most recent call last):
  File "C:\Users\Innovo\PycharmProjects\linkedmatrix\venv\lib\site-packages\django_redis\cache.py", line 31, in _decorator
    return method(self, *args, **kwargs)
  File "C:\Users\Innovo\PycharmProjects\linkedmatrix\venv\lib\site-packages\django_redis\cache.py", line 98, in _get
    return self.client.get(key, default=default, version=version, client=client)
  File "C:\Users\Innovo\PycharmProjects\linkedmatrix\venv\lib\site-packages\django_redis\client\default.py", line 260, in get
    raise ConnectionInterrupted(connection=client) from e
django_redis.exceptions.ConnectionInterrupted: Redis ConnectionError: Error 10061 connecting to 127.0.0.1:6379. No connection could be made because the target machine actively refused it.

During handling of the above exception, another exception occurred:

Traceback (most recent call last):
  File "C:\Users\Innovo\PycharmProjects\linkedmatrix\venv\lib\site-packages\django\core\handlers\exception.py", line 55, in inner
    response = get_response(request)
  File "C:\Users\Innovo\PycharmProjects\linkedmatrix\custommiddle\mysite\middlewares.py", line 29, in my_ip
    ipcome = cache.get(ip)
  File "C:\Users\Innovo\PycharmProjects\linkedmatrix\venv\lib\site-packages\django_redis\cache.py", line 91, in get
    value = self._get(key, default, version, client)
  File "C:\Users\Innovo\PycharmProjects\linkedmatrix\venv\lib\site-packages\django_redis\cache.py", line 38, in _decorator
    raise e.__cause__
  File "C:\Users\Innovo\PycharmProjects\linkedmatrix\venv\lib\site-packages\django_redis\client\default.py", line 258, in get
    value = client.get(key)
  File "C:\Users\Innovo\PycharmProjects\linkedmatrix\venv\lib\site-packages\redis\commands\core.py", line 1600, in get
    return self.execute_command("GET", name)
  File "C:\Users\Innovo\PycharmProjects\linkedmatrix\venv\lib\site-packages\redis\client.py", line 1215, in execute_command
    conn = self.connection or pool.get_connection(command_name, **options)
  File "C:\Users\Innovo\PycharmProjects\linkedmatrix\venv\lib\site-packages\redis\connection.py", line 1386, in get_connection
    connection.connect()
  File "C:\Users\Innovo\PycharmProjects\linkedmatrix\venv\lib\site-packages\redis\connection.py", line 620, in connect
    raise ConnectionError(self._error_message(e))
redis.exceptions.ConnectionError: Error 10061 connecting to 127.0.0.1:6379. No connection could be made because the target machine actively refused it.
User come this  127.0.0.1on page
Homepage was accessed at 2022-04-26 10:48:25.303706 hours! with that  
Internal Server Error: /admin/
Traceback (most recent call last):
  File "C:\Users\Innovo\PycharmProjects\linkedmatrix\venv\lib\site-packages\django\core\handlers\exception.py", line 55, in inner
    response = get_response(request)
  File "C:\Users\Innovo\PycharmProjects\linkedmatrix\custommiddle\mysite\middlewares.py", line 30, in my_ip
    iplast = cache.set(ipcome)
TypeError: set() missing 1 required positional argument: 'value'
User come this  127.0.0.1on page
Homepage was accessed at 2022-04-26 10:48:25.303706 hours! with that  
Internal Server Error: /favicon.ico
Traceback (most recent call last):
  File "C:\Users\Innovo\PycharmProjects\linkedmatrix\venv\lib\site-packages\django\core\handlers\exception.py", line 55, in inner
    response = get_response(request)
  File "C:\Users\Innovo\PycharmProjects\linkedmatrix\custommiddle\mysite\middlewares.py", line 30, in my_ip
    iplast = cache.set(ipcome)
TypeError: set() missing 1 required positional argument: 'value'
User come this  127.0.0.1on page
Homepage was accessed at 2022-04-26 10:48:31.373732 hours! with that  
Internal Server Error: /admin/
Traceback (most recent call last):
  File "C:\Users\Innovo\PycharmProjects\linkedmatrix\venv\lib\site-packages\django\core\handlers\exception.py", line 55, in inner
    response = get_response(request)
  File "C:\Users\Innovo\PycharmProjects\linkedmatrix\custommiddle\mysite\middlewares.py", line 30, in my_ip
    iplast = cache.set(ipcome)
TypeError: set() missing 1 required positional argument: 'value'
User come this  127.0.0.1on page
Homepage was accessed at 2022-04-26 10:48:31.373732 hours! with that  
Internal Server Error: /favicon.ico
Traceback (most recent call last):
  File "C:\Users\Innovo\PycharmProjects\linkedmatrix\venv\lib\site-packages\django\core\handlers\exception.py", line 55, in inner
    response = get_response(request)
  File "C:\Users\Innovo\PycharmProjects\linkedmatrix\custommiddle\mysite\middlewares.py", line 30, in my_ip
    iplast = cache.set(ipcome)
TypeError: set() missing 1 required positional argument: 'value'
User come this  127.0.0.1on page
Homepage was accessed at 2022-04-26 11:57:10.267726 hours! with that  
Internal Server Error: /admin/
Traceback (most recent call last):
  File "C:\Users\Innovo\PycharmProjects\linkedmatrix\venv\lib\site-packages\django_redis\cache.py", line 31, in _decorator
    return method(self, *args, **kwargs)
  File "C:\Users\Innovo\PycharmProjects\linkedmatrix\venv\lib\site-packages\django_redis\cache.py", line 98, in _get
    return self.client.get(key, default=default, version=version, client=client)
  File "C:\Users\Innovo\PycharmProjects\linkedmatrix\venv\lib\site-packages\django_redis\client\default.py", line 260, in get
    raise ConnectionInterrupted(connection=client) from e
django_redis.exceptions.ConnectionInterrupted: Redis ConnectionError: Error 10061 connecting to 127.0.0.1:6379. No connection could be made because the target machine actively refused it.

During handling of the above exception, another exception occurred:

Traceback (most recent call last):
  File "C:\Users\Innovo\PycharmProjects\linkedmatrix\venv\lib\site-packages\django\core\handlers\exception.py", line 55, in inner
    response = get_response(request)
  File "C:\Users\Innovo\PycharmProjects\linkedmatrix\custommiddle\mysite\middlewares.py", line 29, in my_ip
    ipcome = cache.get(ip)
  File "C:\Users\Innovo\PycharmProjects\linkedmatrix\venv\lib\site-packages\django_redis\cache.py", line 91, in get
    value = self._get(key, default, version, client)
  File "C:\Users\Innovo\PycharmProjects\linkedmatrix\venv\lib\site-packages\django_redis\cache.py", line 38, in _decorator
    raise e.__cause__
  File "C:\Users\Innovo\PycharmProjects\linkedmatrix\venv\lib\site-packages\django_redis\client\default.py", line 258, in get
    value = client.get(key)
  File "C:\Users\Innovo\PycharmProjects\linkedmatrix\venv\lib\site-packages\redis\commands\core.py", line 1600, in get
    return self.execute_command("GET", name)
  File "C:\Users\Innovo\PycharmProjects\linkedmatrix\venv\lib\site-packages\redis\client.py", line 1215, in execute_command
    conn = self.connection or pool.get_connection(command_name, **options)
  File "C:\Users\Innovo\PycharmProjects\linkedmatrix\venv\lib\site-packages\redis\connection.py", line 1386, in get_connection
    connection.connect()
  File "C:\Users\Innovo\PycharmProjects\linkedmatrix\venv\lib\site-packages\redis\connection.py", line 620, in connect
    raise ConnectionError(self._error_message(e))
redis.exceptions.ConnectionError: Error 10061 connecting to 127.0.0.1:6379. No connection could be made because the target machine actively refused it.
User come this  127.0.0.1on page
Homepage was accessed at 2022-04-26 11:57:10.267726 hours! with that  
Internal Server Error: /favicon.ico
Traceback (most recent call last):
  File "C:\Users\Innovo\PycharmProjects\linkedmatrix\venv\lib\site-packages\django_redis\cache.py", line 31, in _decorator
    return method(self, *args, **kwargs)
  File "C:\Users\Innovo\PycharmProjects\linkedmatrix\venv\lib\site-packages\django_redis\cache.py", line 98, in _get
    return self.client.get(key, default=default, version=version, client=client)
  File "C:\Users\Innovo\PycharmProjects\linkedmatrix\venv\lib\site-packages\django_redis\client\default.py", line 260, in get
    raise ConnectionInterrupted(connection=client) from e
django_redis.exceptions.ConnectionInterrupted: Redis ConnectionError: Error 10061 connecting to 127.0.0.1:6379. No connection could be made because the target machine actively refused it.

During handling of the above exception, another exception occurred:

Traceback (most recent call last):
  File "C:\Users\Innovo\PycharmProjects\linkedmatrix\venv\lib\site-packages\django\core\handlers\exception.py", line 55, in inner
    response = get_response(request)
  File "C:\Users\Innovo\PycharmProjects\linkedmatrix\custommiddle\mysite\middlewares.py", line 29, in my_ip
    ipcome = cache.get(ip)
  File "C:\Users\Innovo\PycharmProjects\linkedmatrix\venv\lib\site-packages\django_redis\cache.py", line 91, in get
    value = self._get(key, default, version, client)
  File "C:\Users\Innovo\PycharmProjects\linkedmatrix\venv\lib\site-packages\django_redis\cache.py", line 38, in _decorator
    raise e.__cause__
  File "C:\Users\Innovo\PycharmProjects\linkedmatrix\venv\lib\site-packages\django_redis\client\default.py", line 258, in get
    value = client.get(key)
  File "C:\Users\Innovo\PycharmProjects\linkedmatrix\venv\lib\site-packages\redis\commands\core.py", line 1600, in get
    return self.execute_command("GET", name)
  File "C:\Users\Innovo\PycharmProjects\linkedmatrix\venv\lib\site-packages\redis\client.py", line 1215, in execute_command
    conn = self.connection or pool.get_connection(command_name, **options)
  File "C:\Users\Innovo\PycharmProjects\linkedmatrix\venv\lib\site-packages\redis\connection.py", line 1386, in get_connection
    connection.connect()
  File "C:\Users\Innovo\PycharmProjects\linkedmatrix\venv\lib\site-packages\redis\connection.py", line 620, in connect
    raise ConnectionError(self._error_message(e))
redis.exceptions.ConnectionError: Error 10061 connecting to 127.0.0.1:6379. No connection could be made because the target machine actively refused it.
